<?xml version="1.0"?>
<robot name="diff_drive_robot">
  <material name="blue">
    <color rgba="0.2 0.7 0.9 1" />
  </material>
  <material name="black">
    <color rgba="0.2 0.2 0.2 1" />
  </material>

  <link name="base_link">
    <visual>
      <geometry>
        <cylinder radius="0.15" length="0.08" />
      </geometry>
      <material name="blue" />
    </visual>
    <collision>
      <geometry>
        <cylinder radius="0.15" length="0.08" />
      </geometry>
    </collision>
    <inertial>
      <mass value="12.0" />
      <inertia ixx="0.07" ixy="0.0" ixz="0.0" iyy="0.07" iyz="0.0" izz="0.13" />
    </inertial>
  </link>

  <link name="left_wheel">
    <visual>
      <geometry>
        <cylinder radius="0.0975" length="0.04" />
      </geometry>
      <material name="black" />
    </visual>
    <collision>
      <geometry>
        <cylinder radius="0.0975" length="0.04" />
      </geometry>
    </collision>
    <inertial>
      <mass value="1.0" />
      <inertia ixx="0.0025" ixy="0.0" ixz="0.0" iyy="0.0025" iyz="0.0" izz="0.005" />
    </inertial>
  </link>

  <link name="right_wheel">
    <visual>
      <geometry>
        <cylinder radius="0.0975" length="0.04" />
      </geometry>
      <material name="black" />
    </visual>
    <collision>
      <geometry>
        <cylinder radius="0.0975" length="0.04" />
      </geometry>
    </collision>
    <inertial>
      <mass value="1.0" />
      <inertia ixx="0.0025" ixy="0.0" ixz="0.0" iyy="0.0025" iyz="0.0" izz="0.005" />
    </inertial>
  </link>

  <joint name="left_wheel_joint" type="continuous">
    <parent link="base_link" />
    <child link="left_wheel" />
    <origin xyz="0 0.1905 -0.02" rpy="-1.57079632679 0 0" />
    <axis xyz="0 0 1" />
  </joint>

  <joint name="right_wheel_joint" type="continuous">
    <parent link="base_link" />
    <child link="right_wheel" />
    <origin xyz="0 -0.1905 -0.02" rpy="-1.57079632679 0 0" />
    <axis xyz="0 0 1" />
  </joint>

</robot>
